<?xml version="1.0" ?>
<sdf version="1.7">
  <model name="humanoid_robot">
    <!-- Base Link -->
    <link name="base_link">
      <inertial>
        <mass>10.0</mass>
        <inertia>
          <ixx>0.1</ixx>
          <ixy>0.0</ixy>
          <ixz>0.0</ixz>
          <iyy>0.1</iyy>
          <iyz>0.0</iyz>
          <izz>0.1</izz>
        </inertia>
      </inertial>
      <visual name="base_visual">
        <geometry>
          <box>
            <size>0.3 0.2 0.4</size>
          </box>
        </geometry>
        <material>
          <ambient>0.0 0.0 1.0 1.0</ambient>
          <diffuse>0.0 0.0 1.0 1.0</diffuse>
        </material>
      </visual>
      <collision name="base_collision">
        <geometry>
          <box>
            <size>0.3 0.2 0.4</size>
          </box>
        </geometry>
      </collision>
    </link>

    <!-- Torso -->
    <link name="torso">
      <inertial>
        <mass>5.0</mass>
        <inertia>
          <ixx>0.2</ixx>
          <ixy>0.0</ixy>
          <ixz>0.0</ixz>
          <iyy>0.2</iyy>
          <iyz>0.0</iyz>
          <izz>0.2</izz>
        </inertia>
      </inertial>
      <visual name="torso_visual">
        <geometry>
          <box>
            <size>0.2 0.3 0.5</size>
          </box>
        </geometry>
        <material>
          <ambient>0.0 1.0 1.0 1.0</ambient>
          <diffuse>0.0 1.0 1.0 1.0</diffuse>
        </material>
      </visual>
      <collision name="torso_collision">
        <geometry>
          <box>
            <size>0.2 0.3 0.5</size>
          </box>
        </geometry>
      </collision>
    </link>

    <joint name="base_to_torso" type="fixed">
      <parent>base_link</parent>
      <child>torso</child>
      <pose>0 0 0.3 0 0 0</pose>
    </joint>

    <!-- Head -->
    <link name="head">
      <inertial>
        <mass>2.0</mass>
        <inertia>
          <ixx>0.01</ixx>
          <ixy>0.0</ixy>
          <ixz>0.0</ixz>
          <iyy>0.01</iyy>
          <iyz>0.0</iyz>
          <izz>0.01</izz>
        </inertia>
      </inertial>
      <visual name="head_visual">
        <geometry>
          <sphere>
            <radius>0.1</radius>
          </sphere>
        </geometry>
        <material>
          <ambient>1.0 0.8 0.6 1.0</ambient>
          <diffuse>1.0 0.8 0.6 1.0</diffuse>
        </material>
      </visual>
      <collision name="head_collision">
        <geometry>
          <sphere>
            <radius>0.1</radius>
          </sphere>
        </geometry>
      </collision>
    </link>

    <joint name="torso_to_head" type="revolute">
      <parent>torso</parent>
      <child>head</child>
      <axis>
        <xyz>0 1 0</xyz>
        <limit>
          <lower>-0.5</lower>
          <upper>0.5</upper>
          <effort>10.0</effort>
          <velocity>1.0</velocity>
        </limit>
      </axis>
      <pose>0 0 0.35 0 0 0</pose>
    </joint>

    <!-- Left Arm -->
    <link name="left_upper_arm">
      <inertial>
        <mass>1.0</mass>
        <inertia>
          <ixx>0.01</ixx>
          <ixy>0.0</ixy>
          <ixz>0.0</ixz>
          <iyy>0.01</iyy>
          <iyz>0.0</iyz>
          <izz>0.01</izz>
        </inertia>
      </inertial>
      <visual name="left_upper_arm_visual">
        <geometry>
          <cylinder>
            <length>0.3</length>
            <radius>0.05</radius>
          </cylinder>
        </geometry>
        <material>
          <ambient>0.0 1.0 0.0 1.0</ambient>
          <diffuse>0.0 1.0 0.0 1.0</diffuse>
        </material>
      </visual>
      <collision name="left_upper_arm_collision">
        <geometry>
          <cylinder>
            <length>0.3</length>
            <radius>0.05</radius>
          </cylinder>
        </geometry>
      </collision>
    </link>

    <joint name="left_shoulder" type="revolute">
      <parent>torso</parent>
      <child>left_upper_arm</child>
      <axis>
        <xyz>0 1 0</xyz>
        <limit>
          <lower>-1.57</lower>
          <upper>1.57</upper>
          <effort>10.0</effort>
          <velocity>1.0</velocity>
        </limit>
      </axis>
      <pose>0.1 0.15 0.1 0 0 0</pose>
    </joint>

    <!-- Right Arm -->
    <link name="right_upper_arm">
      <inertial>
        <mass>1.0</mass>
        <inertia>
          <ixx>0.01</ixx>
          <ixy>0.0</ixy>
          <ixz>0.0</ixz>
          <iyy>0.01</iyy>
          <iyz>0.0</iyz>
          <izz>0.01</izz>
        </inertia>
      </inertial>
      <visual name="right_upper_arm_visual">
        <geometry>
          <cylinder>
            <length>0.3</length>
            <radius>0.05</radius>
          </cylinder>
        </geometry>
        <material>
          <ambient>0.0 1.0 0.0 1.0</ambient>
          <diffuse>0.0 1.0 0.0 1.0</diffuse>
        </material>
      </visual>
      <collision name="right_upper_arm_collision">
        <geometry>
          <cylinder>
            <length>0.3</length>
            <radius>0.05</radius>
          </cylinder>
        </geometry>
      </collision>
    </link>

    <joint name="right_shoulder" type="revolute">
      <parent>torso</parent>
      <child>right_upper_arm</child>
      <axis>
        <xyz>0 1 0</xyz>
        <limit>
          <lower>-1.57</lower>
          <upper>1.57</upper>
          <effort>10.0</effort>
          <velocity>1.0</velocity>
        </limit>
      </axis>
      <pose>0.1 -0.15 0.1 0 0 0</pose>
    </joint>

    <!-- Left Leg -->
    <link name="left_upper_leg">
      <inertial>
        <mass>2.0</mass>
        <inertia>
          <ixx>0.05</ixx>
          <ixy>0.0</ixy>
          <ixz>0.0</ixz>
          <iyy>0.05</iyy>
          <iyz>0.0</iyz>
          <izz>0.05</izz>
        </inertia>
      </inertial>
      <visual name="left_upper_leg_visual">
        <geometry>
          <cylinder>
            <length>0.4</length>
            <radius>0.06</radius>
          </cylinder>
        </geometry>
        <material>
          <ambient>1.0 0.0 0.0 1.0</ambient>
          <diffuse>1.0 0.0 0.0 1.0</diffuse>
        </material>
      </visual>
      <collision name="left_upper_leg_collision">
        <geometry>
          <cylinder>
            <length>0.4</length>
            <radius>0.06</radius>
          </cylinder>
        </geometry>
      </collision>
    </link>

    <joint name="left_hip" type="revolute">
      <parent>base_link</parent>
      <child>left_upper_leg</child>
      <axis>
        <xyz>0 1 0</xyz>
        <limit>
          <lower>-1.0</lower>
          <upper>0.5</upper>
          <effort>15.0</effort>
          <velocity>1.0</velocity>
        </limit>
      </axis>
      <pose>-0.1 0.1 -0.1 0 0 0</pose>
    </joint>

    <!-- Right Leg -->
    <link name="right_upper_leg">
      <inertial>
        <mass>2.0</mass>
        <inertia>
          <ixx>0.05</ixx>
          <ixy>0.0</ixy>
          <ixz>0.0</ixz>
          <iyy>0.05</iyy>
          <iyz>0.0</iyz>
          <izz>0.05</izz>
        </inertia>
      </inertial>
      <visual name="right_upper_leg_visual">
        <geometry>
          <cylinder>
            <length>0.4</length>
            <radius>0.06</radius>
          </cylinder>
        </geometry>
        <material>
          <ambient>1.0 0.0 0.0 1.0</ambient>
          <diffuse>1.0 0.0 0.0 1.0</diffuse>
        </material>
      </visual>
      <collision name="right_upper_leg_collision">
        <geometry>
          <cylinder>
            <length>0.4</length>
            <radius>0.06</radius>
          </cylinder>
        </geometry>
      </collision>
    </link>

    <joint name="right_hip" type="revolute">
      <parent>base_link</parent>
      <child>right_upper_leg</child>
      <axis>
        <xyz>0 1 0</xyz>
        <limit>
          <lower>-1.0</lower>
          <upper>0.5</upper>
          <effort>15.0</effort>
          <velocity>1.0</velocity>
        </limit>
      </axis>
      <pose>-0.1 -0.1 -0.1 0 0 0</pose>
    </joint>

    <!-- Sensors -->
    <!-- IMU Sensor -->
    <sensor name="imu_sensor" type="imu">
      <always_on>true</always_on>
      <update_rate>100</update_rate>
      <pose>0 0 0.1 0 0 0</pose>
    </sensor>

    <!-- LiDAR Sensor -->
    <sensor name="lidar_sensor" type="ray">
      <always_on>true</always_on>
      <update_rate>10</update_rate>
      <pose>0.15 0 0.1 0 0 0</pose>
      <ray>
        <scan>
          <horizontal>
            <samples>360</samples>
            <resolution>1</resolution>
            <min_angle>-3.14159</min_angle>
            <max_angle>3.14159</max_angle>
          </horizontal>
        </scan>
        <range>
          <min>0.1</min>
          <max>10.0</max>
          <resolution>0.01</resolution>
        </range>
      </ray>
    </sensor>

    <!-- Depth Camera Sensor -->
    <sensor name="depth_camera" type="depth">
      <always_on>true</always_on>
      <update_rate>30</update_rate>
      <pose>0.15 0 0.05 0 0 0</pose>
      <camera>
        <horizontal_fov>1.047</horizontal_fov>
        <image>
          <width>640</width>
          <height>480</height>
          <format>R8G8B8</format>
        </image>
        <clip>
          <near>0.1</near>
          <far>10</far>
        </clip>
      </camera>
    </sensor>
  </model>
</sdf>